2025-06-26 22:05:22,790 - INFO - ✅ Flask导入成功
2025-06-26 22:05:22,793 - INFO - 🚀 启动调试版Flask应用...
2025-06-26 22:05:22,793 - INFO - 📍 访问 http://127.0.0.1:5001
2025-06-26 22:05:22,839 - INFO - [31m[1mWARNING: This is a development server. Do not use it in a production deployment. Use a production WSGI server instead.[0m
 * Running on http://127.0.0.1:5001
2025-06-26 22:05:22,840 - INFO - [33mPress CTRL+C to quit[0m
2025-06-26 22:05:25,847 - INFO - 开始处理首页请求
2025-06-26 22:05:26,504 - INFO - Note: NumExpr detected 16 cores but "NUMEXPR_MAX_THREADS" not set, so enforcing safe limit of 8.
2025-06-26 22:05:26,504 - INFO - NumExpr defaulting to 8 threads.
2025-06-26 22:05:26,936 - INFO - ✅ pandas导入成功
2025-06-26 22:05:27,073 - INFO - ✅ pyecharts导入成功
2025-06-26 22:05:27,074 - INFO - ✅ 测试数据准备完成
2025-06-26 22:05:27,074 - INFO - ✅ 首页HTML生成成功
2025-06-26 22:05:27,074 - INFO - 127.0.0.1 - - [26/Jun/2025 22:05:27] "GET / HTTP/1.1" 200 -
2025-06-26 22:05:27,661 - ERROR - 未捕获异常: 404 Not Found: The requested URL was not found on the server. If you entered the URL manually please check your spelling and try again.
2025-06-26 22:05:27,664 - ERROR - 详细信息: Traceback (most recent call last):
  File "C:\Users\86180\AppData\Roaming\Python\Python312\site-packages\flask\app.py", line 1484, in full_dispatch_request
    rv = self.dispatch_request()
         ^^^^^^^^^^^^^^^^^^^^^^^
  File "C:\Users\86180\AppData\Roaming\Python\Python312\site-packages\flask\app.py", line 1458, in dispatch_request
    self.raise_routing_exception(req)
  File "C:\Users\86180\AppData\Roaming\Python\Python312\site-packages\flask\app.py", line 1440, in raise_routing_exception
    raise request.routing_exception  # type: ignore
    ^^^^^^^^^^^^^^^^^^^^^^^^^^^^^^^
  File "C:\Users\86180\AppData\Roaming\Python\Python312\site-packages\flask\ctx.py", line 353, in match_request
    result = self.url_adapter.match(return_rule=True)  # type: ignore
             ^^^^^^^^^^^^^^^^^^^^^^^^^^^^^^^^^^^^^^^^
  File "C:\Users\86180\AppData\Roaming\Python\Python312\site-packages\werkzeug\routing\map.py", line 655, in match
    raise NotFound() from None
werkzeug.exceptions.NotFound: 404 Not Found: The requested URL was not found on the server. If you entered the URL manually please check your spelling and try again.

2025-06-26 22:05:27,667 - INFO - 127.0.0.1 - - [26/Jun/2025 22:05:27] "[35m[1mGET /favicon.ico HTTP/1.1[0m" 500 -
2025-06-26 22:05:30,482 - INFO - 开始处理测试页面
2025-06-26 22:05:30,822 - INFO - 127.0.0.1 - - [26/Jun/2025 22:05:30] "GET /test HTTP/1.1" 200 -
2025-06-26 22:05:31,120 - ERROR - 未捕获异常: 404 Not Found: The requested URL was not found on the server. If you entered the URL manually please check your spelling and try again.
2025-06-26 22:05:31,123 - ERROR - 详细信息: Traceback (most recent call last):
  File "C:\Users\86180\AppData\Roaming\Python\Python312\site-packages\flask\app.py", line 1484, in full_dispatch_request
    rv = self.dispatch_request()
         ^^^^^^^^^^^^^^^^^^^^^^^
  File "C:\Users\86180\AppData\Roaming\Python\Python312\site-packages\flask\app.py", line 1458, in dispatch_request
    self.raise_routing_exception(req)
  File "C:\Users\86180\AppData\Roaming\Python\Python312\site-packages\flask\app.py", line 1440, in raise_routing_exception
    raise request.routing_exception  # type: ignore
    ^^^^^^^^^^^^^^^^^^^^^^^^^^^^^^^
  File "C:\Users\86180\AppData\Roaming\Python\Python312\site-packages\flask\ctx.py", line 353, in match_request
    result = self.url_adapter.match(return_rule=True)  # type: ignore
             ^^^^^^^^^^^^^^^^^^^^^^^^^^^^^^^^^^^^^^^^
  File "C:\Users\86180\AppData\Roaming\Python\Python312\site-packages\werkzeug\routing\map.py", line 655, in match
    raise NotFound() from None
werkzeug.exceptions.NotFound: 404 Not Found: The requested URL was not found on the server. If you entered the URL manually please check your spelling and try again.

2025-06-26 22:05:31,125 - INFO - 127.0.0.1 - - [26/Jun/2025 22:05:31] "[35m[1mGET /favicon.ico HTTP/1.1[0m" 500 -
2025-06-26 22:05:34,166 - INFO - 开始处理首页请求
2025-06-26 22:05:34,166 - INFO - ✅ pandas导入成功
2025-06-26 22:05:34,166 - INFO - ✅ pyecharts导入成功
2025-06-26 22:05:34,166 - INFO - ✅ 测试数据准备完成
2025-06-26 22:05:34,167 - INFO - ✅ 首页HTML生成成功
2025-06-26 22:05:34,167 - INFO - 127.0.0.1 - - [26/Jun/2025 22:05:34] "GET / HTTP/1.1" 200 -
2025-06-26 22:05:34,435 - ERROR - 未捕获异常: 404 Not Found: The requested URL was not found on the server. If you entered the URL manually please check your spelling and try again.
2025-06-26 22:05:34,437 - ERROR - 详细信息: Traceback (most recent call last):
  File "C:\Users\86180\AppData\Roaming\Python\Python312\site-packages\flask\app.py", line 1484, in full_dispatch_request
    rv = self.dispatch_request()
         ^^^^^^^^^^^^^^^^^^^^^^^
  File "C:\Users\86180\AppData\Roaming\Python\Python312\site-packages\flask\app.py", line 1458, in dispatch_request
    self.raise_routing_exception(req)
  File "C:\Users\86180\AppData\Roaming\Python\Python312\site-packages\flask\app.py", line 1440, in raise_routing_exception
    raise request.routing_exception  # type: ignore
    ^^^^^^^^^^^^^^^^^^^^^^^^^^^^^^^
  File "C:\Users\86180\AppData\Roaming\Python\Python312\site-packages\flask\ctx.py", line 353, in match_request
    result = self.url_adapter.match(return_rule=True)  # type: ignore
             ^^^^^^^^^^^^^^^^^^^^^^^^^^^^^^^^^^^^^^^^
  File "C:\Users\86180\AppData\Roaming\Python\Python312\site-packages\werkzeug\routing\map.py", line 655, in match
    raise NotFound() from None
werkzeug.exceptions.NotFound: 404 Not Found: The requested URL was not found on the server. If you entered the URL manually please check your spelling and try again.

2025-06-26 22:05:34,440 - INFO - 127.0.0.1 - - [26/Jun/2025 22:05:34] "[35m[1mGET /favicon.ico HTTP/1.1[0m" 500 -
2025-06-26 22:05:35,221 - INFO - 开始处理象限图页面
2025-06-26 22:05:35,223 - INFO - 127.0.0.1 - - [26/Jun/2025 22:05:35] "GET /chart/competitor HTTP/1.1" 200 -
2025-06-26 22:05:36,873 - ERROR - 未捕获异常: 404 Not Found: The requested URL was not found on the server. If you entered the URL manually please check your spelling and try again.
2025-06-26 22:05:36,875 - ERROR - 详细信息: Traceback (most recent call last):
  File "C:\Users\86180\AppData\Roaming\Python\Python312\site-packages\flask\app.py", line 1484, in full_dispatch_request
    rv = self.dispatch_request()
         ^^^^^^^^^^^^^^^^^^^^^^^
  File "C:\Users\86180\AppData\Roaming\Python\Python312\site-packages\flask\app.py", line 1458, in dispatch_request
    self.raise_routing_exception(req)
  File "C:\Users\86180\AppData\Roaming\Python\Python312\site-packages\flask\app.py", line 1440, in raise_routing_exception
    raise request.routing_exception  # type: ignore
    ^^^^^^^^^^^^^^^^^^^^^^^^^^^^^^^
  File "C:\Users\86180\AppData\Roaming\Python\Python312\site-packages\flask\ctx.py", line 353, in match_request
    result = self.url_adapter.match(return_rule=True)  # type: ignore
             ^^^^^^^^^^^^^^^^^^^^^^^^^^^^^^^^^^^^^^^^
  File "C:\Users\86180\AppData\Roaming\Python\Python312\site-packages\werkzeug\routing\map.py", line 655, in match
    raise NotFound() from None
werkzeug.exceptions.NotFound: 404 Not Found: The requested URL was not found on the server. If you entered the URL manually please check your spelling and try again.

2025-06-26 22:05:36,879 - INFO - 127.0.0.1 - - [26/Jun/2025 22:05:36] "[35m[1mGET /favicon.ico HTTP/1.1[0m" 500 -
2025-06-26 22:05:38,525 - INFO - 开始处理首页请求
2025-06-26 22:05:38,525 - INFO - ✅ pandas导入成功
2025-06-26 22:05:38,526 - INFO - ✅ pyecharts导入成功
2025-06-26 22:05:38,526 - INFO - ✅ 测试数据准备完成
2025-06-26 22:05:38,526 - INFO - ✅ 首页HTML生成成功
2025-06-26 22:05:38,526 - INFO - 127.0.0.1 - - [26/Jun/2025 22:05:38] "GET / HTTP/1.1" 200 -
2025-06-26 22:05:38,794 - ERROR - 未捕获异常: 404 Not Found: The requested URL was not found on the server. If you entered the URL manually please check your spelling and try again.
2025-06-26 22:05:38,796 - ERROR - 详细信息: Traceback (most recent call last):
  File "C:\Users\86180\AppData\Roaming\Python\Python312\site-packages\flask\app.py", line 1484, in full_dispatch_request
    rv = self.dispatch_request()
         ^^^^^^^^^^^^^^^^^^^^^^^
  File "C:\Users\86180\AppData\Roaming\Python\Python312\site-packages\flask\app.py", line 1458, in dispatch_request
    self.raise_routing_exception(req)
  File "C:\Users\86180\AppData\Roaming\Python\Python312\site-packages\flask\app.py", line 1440, in raise_routing_exception
    raise request.routing_exception  # type: ignore
    ^^^^^^^^^^^^^^^^^^^^^^^^^^^^^^^
  File "C:\Users\86180\AppData\Roaming\Python\Python312\site-packages\flask\ctx.py", line 353, in match_request
    result = self.url_adapter.match(return_rule=True)  # type: ignore
             ^^^^^^^^^^^^^^^^^^^^^^^^^^^^^^^^^^^^^^^^
  File "C:\Users\86180\AppData\Roaming\Python\Python312\site-packages\werkzeug\routing\map.py", line 655, in match
    raise NotFound() from None
werkzeug.exceptions.NotFound: 404 Not Found: The requested URL was not found on the server. If you entered the URL manually please check your spelling and try again.

2025-06-26 22:05:38,798 - INFO - 127.0.0.1 - - [26/Jun/2025 22:05:38] "[35m[1mGET /favicon.ico HTTP/1.1[0m" 500 -
2025-06-26 22:05:39,231 - INFO - 127.0.0.1 - - [26/Jun/2025 22:05:39] "GET /simple HTTP/1.1" 200 -
2025-06-26 22:05:39,506 - ERROR - 未捕获异常: 404 Not Found: The requested URL was not found on the server. If you entered the URL manually please check your spelling and try again.
2025-06-26 22:05:39,508 - ERROR - 详细信息: Traceback (most recent call last):
  File "C:\Users\86180\AppData\Roaming\Python\Python312\site-packages\flask\app.py", line 1484, in full_dispatch_request
    rv = self.dispatch_request()
         ^^^^^^^^^^^^^^^^^^^^^^^
  File "C:\Users\86180\AppData\Roaming\Python\Python312\site-packages\flask\app.py", line 1458, in dispatch_request
    self.raise_routing_exception(req)
  File "C:\Users\86180\AppData\Roaming\Python\Python312\site-packages\flask\app.py", line 1440, in raise_routing_exception
    raise request.routing_exception  # type: ignore
    ^^^^^^^^^^^^^^^^^^^^^^^^^^^^^^^
  File "C:\Users\86180\AppData\Roaming\Python\Python312\site-packages\flask\ctx.py", line 353, in match_request
    result = self.url_adapter.match(return_rule=True)  # type: ignore
             ^^^^^^^^^^^^^^^^^^^^^^^^^^^^^^^^^^^^^^^^
  File "C:\Users\86180\AppData\Roaming\Python\Python312\site-packages\werkzeug\routing\map.py", line 655, in match
    raise NotFound() from None
werkzeug.exceptions.NotFound: 404 Not Found: The requested URL was not found on the server. If you entered the URL manually please check your spelling and try again.

2025-06-26 22:05:39,512 - INFO - 127.0.0.1 - - [26/Jun/2025 22:05:39] "[35m[1mGET /favicon.ico HTTP/1.1[0m" 500 -
2025-06-26 22:05:40,454 - INFO - 开始处理首页请求
2025-06-26 22:05:40,455 - INFO - ✅ pandas导入成功
2025-06-26 22:05:40,455 - INFO - ✅ pyecharts导入成功
2025-06-26 22:05:40,455 - INFO - ✅ 测试数据准备完成
2025-06-26 22:05:40,455 - INFO - ✅ 首页HTML生成成功
2025-06-26 22:05:40,456 - INFO - 127.0.0.1 - - [26/Jun/2025 22:05:40] "GET / HTTP/1.1" 200 -
2025-06-26 22:05:40,721 - ERROR - 未捕获异常: 404 Not Found: The requested URL was not found on the server. If you entered the URL manually please check your spelling and try again.
2025-06-26 22:05:40,723 - ERROR - 详细信息: Traceback (most recent call last):
  File "C:\Users\86180\AppData\Roaming\Python\Python312\site-packages\flask\app.py", line 1484, in full_dispatch_request
    rv = self.dispatch_request()
         ^^^^^^^^^^^^^^^^^^^^^^^
  File "C:\Users\86180\AppData\Roaming\Python\Python312\site-packages\flask\app.py", line 1458, in dispatch_request
    self.raise_routing_exception(req)
  File "C:\Users\86180\AppData\Roaming\Python\Python312\site-packages\flask\app.py", line 1440, in raise_routing_exception
    raise request.routing_exception  # type: ignore
    ^^^^^^^^^^^^^^^^^^^^^^^^^^^^^^^
  File "C:\Users\86180\AppData\Roaming\Python\Python312\site-packages\flask\ctx.py", line 353, in match_request
    result = self.url_adapter.match(return_rule=True)  # type: ignore
             ^^^^^^^^^^^^^^^^^^^^^^^^^^^^^^^^^^^^^^^^
  File "C:\Users\86180\AppData\Roaming\Python\Python312\site-packages\werkzeug\routing\map.py", line 655, in match
    raise NotFound() from None
werkzeug.exceptions.NotFound: 404 Not Found: The requested URL was not found on the server. If you entered the URL manually please check your spelling and try again.

2025-06-26 22:05:40,726 - INFO - 127.0.0.1 - - [26/Jun/2025 22:05:40] "[35m[1mGET /favicon.ico HTTP/1.1[0m" 500 -
2025-06-26 22:05:41,520 - INFO - 127.0.0.1 - - [26/Jun/2025 22:05:41] "GET /debug-info HTTP/1.1" 200 -
2025-06-26 22:05:41,785 - ERROR - 未捕获异常: 404 Not Found: The requested URL was not found on the server. If you entered the URL manually please check your spelling and try again.
2025-06-26 22:05:41,788 - ERROR - 详细信息: Traceback (most recent call last):
  File "C:\Users\86180\AppData\Roaming\Python\Python312\site-packages\flask\app.py", line 1484, in full_dispatch_request
    rv = self.dispatch_request()
         ^^^^^^^^^^^^^^^^^^^^^^^
  File "C:\Users\86180\AppData\Roaming\Python\Python312\site-packages\flask\app.py", line 1458, in dispatch_request
    self.raise_routing_exception(req)
  File "C:\Users\86180\AppData\Roaming\Python\Python312\site-packages\flask\app.py", line 1440, in raise_routing_exception
    raise request.routing_exception  # type: ignore
    ^^^^^^^^^^^^^^^^^^^^^^^^^^^^^^^
  File "C:\Users\86180\AppData\Roaming\Python\Python312\site-packages\flask\ctx.py", line 353, in match_request
    result = self.url_adapter.match(return_rule=True)  # type: ignore
             ^^^^^^^^^^^^^^^^^^^^^^^^^^^^^^^^^^^^^^^^
  File "C:\Users\86180\AppData\Roaming\Python\Python312\site-packages\werkzeug\routing\map.py", line 655, in match
    raise NotFound() from None
werkzeug.exceptions.NotFound: 404 Not Found: The requested URL was not found on the server. If you entered the URL manually please check your spelling and try again.

2025-06-26 22:05:41,790 - INFO - 127.0.0.1 - - [26/Jun/2025 22:05:41] "[35m[1mGET /favicon.ico HTTP/1.1[0m" 500 -
2025-06-26 22:05:45,075 - ERROR - 未捕获异常: 404 Not Found: The requested URL was not found on the server. If you entered the URL manually please check your spelling and try again.
2025-06-26 22:05:45,077 - ERROR - 详细信息: Traceback (most recent call last):
  File "C:\Users\86180\AppData\Roaming\Python\Python312\site-packages\flask\app.py", line 1484, in full_dispatch_request
    rv = self.dispatch_request()
         ^^^^^^^^^^^^^^^^^^^^^^^
  File "C:\Users\86180\AppData\Roaming\Python\Python312\site-packages\flask\app.py", line 1458, in dispatch_request
    self.raise_routing_exception(req)
  File "C:\Users\86180\AppData\Roaming\Python\Python312\site-packages\flask\app.py", line 1440, in raise_routing_exception
    raise request.routing_exception  # type: ignore
    ^^^^^^^^^^^^^^^^^^^^^^^^^^^^^^^
  File "C:\Users\86180\AppData\Roaming\Python\Python312\site-packages\flask\ctx.py", line 353, in match_request
    result = self.url_adapter.match(return_rule=True)  # type: ignore
             ^^^^^^^^^^^^^^^^^^^^^^^^^^^^^^^^^^^^^^^^
  File "C:\Users\86180\AppData\Roaming\Python\Python312\site-packages\werkzeug\routing\map.py", line 655, in match
    raise NotFound() from None
werkzeug.exceptions.NotFound: 404 Not Found: The requested URL was not found on the server. If you entered the URL manually please check your spelling and try again.

2025-06-26 22:05:45,079 - INFO - 127.0.0.1 - - [26/Jun/2025 22:05:45] "[35m[1mGET /favicon.ico HTTP/1.1[0m" 500 -
